<?xml version="1.0" encoding="UTF-8"?>
<testng-results ignored="0" total="4" passed="2" failed="2" skipped="0">
  <reporter-output>
  </reporter-output>
  <suite started-at="2022-03-08T17:50:32 IST" name="Default suite" finished-at="2022-03-08T17:50:32 IST" duration-ms="97">
    <groups>
    </groups>
    <test started-at="2022-03-08T17:50:32 IST" name="Default test" finished-at="2022-03-08T17:50:32 IST" duration-ms="97">
      <class name="pkgSample.sampleTestNG">
        <test-method signature="TestA()[pri:0, instance:pkgSample.sampleTestNG@6193932a]" started-at="2022-03-08T17:50:32 IST" name="TestA" finished-at="2022-03-08T17:50:32 IST" duration-ms="15" status="PASS">
          <reporter-output>
          </reporter-output>
        </test-method> <!-- TestA -->
        <test-method signature="TestB()[pri:0, instance:pkgSample.sampleTestNG@6193932a]" started-at="2022-03-08T17:50:32 IST" name="TestB" finished-at="2022-03-08T17:50:32 IST" duration-ms="6" status="FAIL">
          <exception class="java.lang.AssertionError">
            <message>
              <![CDATA[expected [null] but found [org.testng.asserts.SoftAssert@1aafa419]]]>
            </message>
            <full-stacktrace>
              <![CDATA[java.lang.AssertionError: expected [null] but found [org.testng.asserts.SoftAssert@1aafa419]
at org.testng.Assert.fail(Assert.java:99)
at org.testng.Assert.failNotSame(Assert.java:1033)
at org.testng.Assert.assertNull(Assert.java:965)
at org.testng.Assert.assertNull(Assert.java:953)
at pkgSample.sampleTestNG.TestB(sampleTestNG.java:20)
at java.base/jdk.internal.reflect.NativeMethodAccessorImpl.invoke0(Native Method)
at java.base/jdk.internal.reflect.NativeMethodAccessorImpl.invoke(NativeMethodAccessorImpl.java:77)
at java.base/jdk.internal.reflect.DelegatingMethodAccessorImpl.invoke(DelegatingMethodAccessorImpl.java:43)
at java.base/java.lang.reflect.Method.invoke(Method.java:568)
at org.testng.internal.MethodInvocationHelper.invokeMethod(MethodInvocationHelper.java:133)
at org.testng.internal.TestInvoker.invokeMethod(TestInvoker.java:598)
at org.testng.internal.TestInvoker.invokeTestMethod(TestInvoker.java:173)
at org.testng.internal.MethodRunner.runInSequence(MethodRunner.java:46)
at org.testng.internal.TestInvoker$MethodInvocationAgent.invoke(TestInvoker.java:824)
at org.testng.internal.TestInvoker.invokeTestMethods(TestInvoker.java:146)
at org.testng.internal.TestMethodWorker.invokeTestMethods(TestMethodWorker.java:146)
at org.testng.internal.TestMethodWorker.run(TestMethodWorker.java:128)
at java.base/java.util.ArrayList.forEach(ArrayList.java:1511)
at org.testng.TestRunner.privateRun(TestRunner.java:794)
at org.testng.TestRunner.run(TestRunner.java:596)
at org.testng.SuiteRunner.runTest(SuiteRunner.java:377)
at org.testng.SuiteRunner.runSequentially(SuiteRunner.java:371)
at org.testng.SuiteRunner.privateRun(SuiteRunner.java:332)
at org.testng.SuiteRunner.run(SuiteRunner.java:276)
at org.testng.SuiteRunnerWorker.runSuite(SuiteRunnerWorker.java:53)
at org.testng.SuiteRunnerWorker.run(SuiteRunnerWorker.java:96)
at org.testng.TestNG.runSuitesSequentially(TestNG.java:1212)
at org.testng.TestNG.runSuitesLocally(TestNG.java:1134)
at org.testng.TestNG.runSuites(TestNG.java:1063)
at org.testng.TestNG.run(TestNG.java:1031)
at org.testng.remote.AbstractRemoteTestNG.run(AbstractRemoteTestNG.java:115)
at org.testng.remote.RemoteTestNG.initAndRun(RemoteTestNG.java:251)
at org.testng.remote.RemoteTestNG.main(RemoteTestNG.java:77)
]]>
            </full-stacktrace>
          </exception> <!-- java.lang.AssertionError -->
          <reporter-output>
          </reporter-output>
        </test-method> <!-- TestB -->
        <test-method signature="TestC()[pri:0, instance:pkgSample.sampleTestNG@6193932a]" started-at="2022-03-08T17:50:32 IST" name="TestC" finished-at="2022-03-08T17:50:32 IST" duration-ms="3" status="PASS">
          <reporter-output>
          </reporter-output>
        </test-method> <!-- TestC -->
        <test-method signature="TestD()[pri:0, instance:pkgSample.sampleTestNG@6193932a]" started-at="2022-03-08T17:50:32 IST" name="TestD" finished-at="2022-03-08T17:50:32 IST" duration-ms="6" status="FAIL">
          <exception class="java.lang.AssertionError">
            <message>
              <![CDATA[The following asserts failed:
did not expect [1] but found [1],
expected [true] but found [false]]]>
            </message>
            <full-stacktrace>
              <![CDATA[java.lang.AssertionError: The following asserts failed:
did not expect [1] but found [1],
expected [true] but found [false]
at org.testng.asserts.SoftAssert.assertAll(SoftAssert.java:47)
at org.testng.asserts.SoftAssert.assertAll(SoftAssert.java:31)
at pkgSample.sampleTestNG.TestD(sampleTestNG.java:33)
at java.base/jdk.internal.reflect.NativeMethodAccessorImpl.invoke0(Native Method)
at java.base/jdk.internal.reflect.NativeMethodAccessorImpl.invoke(NativeMethodAccessorImpl.java:77)
at java.base/jdk.internal.reflect.DelegatingMethodAccessorImpl.invoke(DelegatingMethodAccessorImpl.java:43)
at java.base/java.lang.reflect.Method.invoke(Method.java:568)
at org.testng.internal.MethodInvocationHelper.invokeMethod(MethodInvocationHelper.java:133)
at org.testng.internal.TestInvoker.invokeMethod(TestInvoker.java:598)
at org.testng.internal.TestInvoker.invokeTestMethod(TestInvoker.java:173)
at org.testng.internal.MethodRunner.runInSequence(MethodRunner.java:46)
at org.testng.internal.TestInvoker$MethodInvocationAgent.invoke(TestInvoker.java:824)
at org.testng.internal.TestInvoker.invokeTestMethods(TestInvoker.java:146)
at org.testng.internal.TestMethodWorker.invokeTestMethods(TestMethodWorker.java:146)
at org.testng.internal.TestMethodWorker.run(TestMethodWorker.java:128)
at java.base/java.util.ArrayList.forEach(ArrayList.java:1511)
at org.testng.TestRunner.privateRun(TestRunner.java:794)
at org.testng.TestRunner.run(TestRunner.java:596)
at org.testng.SuiteRunner.runTest(SuiteRunner.java:377)
at org.testng.SuiteRunner.runSequentially(SuiteRunner.java:371)
at org.testng.SuiteRunner.privateRun(SuiteRunner.java:332)
at org.testng.SuiteRunner.run(SuiteRunner.java:276)
at org.testng.SuiteRunnerWorker.runSuite(SuiteRunnerWorker.java:53)
at org.testng.SuiteRunnerWorker.run(SuiteRunnerWorker.java:96)
at org.testng.TestNG.runSuitesSequentially(TestNG.java:1212)
at org.testng.TestNG.runSuitesLocally(TestNG.java:1134)
at org.testng.TestNG.runSuites(TestNG.java:1063)
at org.testng.TestNG.run(TestNG.java:1031)
at org.testng.remote.AbstractRemoteTestNG.run(AbstractRemoteTestNG.java:115)
at org.testng.remote.RemoteTestNG.initAndRun(RemoteTestNG.java:251)
at org.testng.remote.RemoteTestNG.main(RemoteTestNG.java:77)
]]>
            </full-stacktrace>
          </exception> <!-- java.lang.AssertionError -->
          <reporter-output>
          </reporter-output>
        </test-method> <!-- TestD -->
      </class> <!-- pkgSample.sampleTestNG -->
    </test> <!-- Default test -->
  </suite> <!-- Default suite -->
</testng-results>
